Workbook

Sheet README
A1: Ma Lakhsmi Stores — Open-to-Buy (OTB) Calculator
A2: Generated 24-Oct-2026 by the otb-calculator skill
A4: What this does
A5: Tells you how much cash you're allowed to spend on stock each month, per category and per sourcing hub (Surat / Burrabazar / Other), without starving rent, salaries or your cash buffer.
A7: Colour legend
A8: Yellow fill + blue text = input you edit. Black = formula (don't touch). Green = pulled from another sheet. Grey italic row above a table = example only, it is NOT counted.
A10: How to use
A11: 1. Inputs — overwrite every yellow cell with your real numbers (all placeholders right now). Category mix and each source split must total 100% (check cells turn red if not).
A12: 2. Monthly OTB — 12-month plan. 'Approved OTB' is your spend limit per category; the source rows tell you how much to carry to Surat vs Burrabazar. Enter confirmed-but-undelivered orders in the yellow 'On order' rows.
A13: 3. Stock Aging — log every purchase lot (date, category, source, qty, cost). Update 'Qty sold' weekly.
A14: 4. Sales Log — once a week, one row per category × source: units sold and sales ₹ (ex-GST, at selling price).
A15: 5. Dashboard — check the ACTION column before every sourcing run. PAUSE = don't buy that category.
... A30: Sales cash is assumed received in the same month (retail, mostly cash/UPI). All money ex-GST. Saree GST rate depends on HSN/price — confirm with your CA.

Sheet Dashboard
A1: Ma Lakhsmi Stores — OTB Dashboard
A2: ="As of "&TEXT(Inputs!$B$11,"dd-mmm-yyyy")&" | Change the date on Inputs!B11" -> As of 24-Oct-2026 | Change the date on Inputs!B11
A4: Current month | B4: =DATE(YEAR(Inputs!$B$11),MONTH(Inputs!$B$11),1) -> 46296
A5: Plan month # (0 = outside plan) | B5: =IFERROR(MATCH(B4,'Monthly OTB'!$C$4:$N$4,0),0) -> 0 | C5: =IF(B5=0,"As-of date is outside the 12-month plan — rebuild or change Inputs!B5","") -> As-of date is outside the 12-month plan — rebuild or change Inputs!B5
A7: Category health & procurement signal
A8: Category | B8: Target mix | C8: Actual stock mix | D8: Variance | E8: Mix signal | F8: Stock on hand (₹ cost) | G8: Sell-through | H8: Weeks of cover | I8: Approved OTB this month | J8: Bought this month | K8: OTB left | L8: ACTION
A9: =Inputs!$A$31 -> Daily Wear | B9: =Inputs!$B$31 -> 0.3 | C9: =IF($F$13=0,0,F9/$F$13) -> 0 | D9: =C9-B9 -> -0.3 | E9: =IF($F$13=0,"No stock yet",IF(D9>Inputs!$B$13,"OVER-INDEXED",IF(D9<-Inputs!$B$13,"UNDER-STOCKED","Balanced"))) -> No stock yet | F9: =SUMIFS('Stock Aging'!$J$6:$J$1005,'Stock Aging'!$C$6:$C$1005,$A9) -> 0 | G9: =IF(SUMIFS('Stock Aging'!$F$6:$F$1005,'Stock Aging'!$C$6:$C$1005,$A9)=0,"",SUMIFS('Stock Aging'!$H$6:$H$1005,'Stock Aging'!$C$6:$C$1005,$A9)/SUMIFS('Stock Aging'!$F$6:$F$1005,'Stock Aging'!$C$6:$C$1005,$A9)) | H9: =IF(SUMIFS('Sales Log'!$E$6:$E$1005,'Sales Log'!$B$6:$B$1005,$A9,'Sales Log'!$A$6:$A$1005,">="&(Inputs!$B$11-27),'Sales Log'!$A$6:$A$1005,"<="&Inputs!$B$11)=0,"",F9/(SUMIFS('Sales Log'!$E$6:$E$1005,'Sales Log'!$B$6:$B$1005,$A9,'Sales Log'!$A$6:$A$1005,">="&(Inputs!$B$11-27),'Sales Log'!$A$6:$A$1005,"<="&Inputs!$B$11)/4*(1-Inputs!$C$31))) | I9: =IF($B$5=0,0,INDEX('Monthly OTB'!$C$15:$N$15,$B$5)) -> 0 | J9: =SUMIFS('Stock Aging'!$N$6:$N$1005,'Stock Aging'!$C$6:$C$1005,$A9,'Stock Aging'!$O$6:$O$1005,$B$4) -> 0 | K9: =I9-J9 -> 0 | L9: =IF(K9<0,"PAUSE – over OTB budget",IF(E9="OVER-INDEXED","PAUSE PROCUREMENT",IF(AND(H9<>"",N(H9)>Inputs!$B$15),"PAUSE – too much cover",IF(AND(G9<>"",N(G9)<Inputs!$B$14),"SLOW – sell-through low",IF(E9="UNDER-STOCKED","PRIORITISE – buy up to OTB","BUY within OTB"))))) -> BUY within OTB
A10: =Inputs!$A$32 -> Festive Handlooms | B10: =Inputs!$B$32 -> 0.35 | C10: =IF($F$13=0,0,F10/$F$13) -> 0 | D10: =C10-B10 -> -0.35 | E10: =IF($F$13=0,"No stock yet",IF(D10>Inputs!$B$13,"OVER-INDEXED",IF(D10<-Inputs!$B$13,"UNDER-STOCKED","Balanced"))) -> No stock yet | F10: =SUMIFS('Stock Aging'!$J$6:$J$1005,'Stock Aging'!$C$6:$C$1005,$A10) -> 0 | G10: =IF(SUMIFS('Stock Aging'!$F$6:$F$1005,'Stock Aging'!$C$6:$C$1005,$A10)=0,"",SUMIFS('Stock Aging'!$H$6:$H$1005,'Stock Aging'!$C$6:$C$1005,$A10)/SUMIFS('Stock Aging'!$F$6:$F$1005,'Stock Aging'!$C$6:$C$1005,$A10)) | H10: =IF(SUMIFS('Sales Log'!$E$6:$E$1005,'Sales Log'!$B$6:$B$1005,$A10,'Sales Log'!$A$6:$A$1005,">="&(Inputs!$B$11-27),'Sales Log'!$A$6:$A$1005,"<="&Inputs!$B$11)=0,"",F10/(SUMIFS('Sales Log'!$E$6:$E$1005,'Sales Log'!$B$6:$B$1005,$A10,'Sales Log'!$A$6:$A$1005,">="&(Inputs!$B$11-27),'Sales Log'!$A$6:$A$1005,"<="&Inputs!$B$11)/4*(1-Inputs!$C$32))) | I10: =IF($B$5=0,0,INDEX('Monthly OTB'!$C$29:$N$29,$B$5)) -> 0 | J10: =SUMIFS('Stock Aging'!$N$6:$N$1005,'Stock Aging'!$C$6:$C$1005,$A10,'Stock Aging'!$O$6:$O$1005,$B$4) -> 0 | K10: =I10-J10 -> 0 | L10: =IF(K10<0,"PAUSE – over OTB budget",IF(E10="OVER-INDEXED","PAUSE PROCUREMENT",IF(AND(H10<>"",N(H10)>Inputs!$B$15),"PAUSE – too much cover",IF(AND(G10<>"",N(G10)<Inputs!$B$14),"SLOW – sell-through low",IF(E10="UNDER-STOCKED","PRIORITISE – buy up to OTB","BUY within OTB"))))) -> BUY within OTB
A11: =Inputs!$A$33 -> Party Wear Synthetics | B11: =Inputs!$B$33 -> 0.25 | C11: =IF($F$13=0,0,F11/$F$13) -> 0 | D11: =C11-B11 -> -0.25 | E11: =IF($F$13=0,"No stock yet",IF(D11>Inputs!$B$13,"OVER-INDEXED",IF(D11<-Inputs!$B$13,"UNDER-STOCKED","Balanced"))) -> No stock yet | F11: =SUMIFS('Stock Aging'!$J$6:$J$1005,'Stock Aging'!$C$6:$C$1005,$A11) -> 0 | G11: =IF(SUMIFS('Stock Aging'!$F$6:$F$1005,'Stock Aging'!$C$6:$C$1005,$A11)=0,"",SUMIFS('Stock Aging'!$H$6:$H$1005,'Stock Aging'!$C$6:$C$1005,$A11)/SUMIFS('Stock Aging'!$F$6:$F$1005,'Stock Aging'!$C$6:$C$1005,$A11)) | H11: =IF(SUMIFS('Sales Log'!$E$6:$E$1005,'Sales Log'!$B$6:$B$1005,$A11,'Sales Log'!$A$6:$A$1005,">="&(Inputs!$B$11-27),'Sales Log'!$A$6:$A$1005,"<="&Inputs!$B$11)=0,"",F11/(SUMIFS('Sales Log'!$E$6:$E$1005,'Sales Log'!$B$6:$B$1005,$A11,'Sales Log'!$A$6:$A$1005,">="&(Inputs!$B$11-27),'Sales Log'!$A$6:$A$1005,"<="&Inputs!$B$11)/4*(1-Inputs!$C$33))) | I11: =IF($B$5=0,0,INDEX('Monthly OTB'!$C$43:$N$43,$B$5)) -> 0 | J11: =SUMIFS('Stock Aging'!$N$6:$N$1005,'Stock Aging'!$C$6:$C$1005,$A11,'Stock Aging'!$O$6:$O$1005,$B$4) -> 0 | K11: =I11-J11 -> 0 | L11: =IF(K11<0,"PAUSE – over OTB budget",IF(E11="OVER-INDEXED","PAUSE PROCUREMENT",IF(AND(H11<>"",N(H11)>Inputs!$B$15),"PAUSE – too much cover",IF(AND(G11<>"",N(G11)<Inputs!$B$14),"SLOW – sell-through low",IF(E11="UNDER-STOCKED","PRIORITISE – buy up to OTB","BUY within OTB"))))) -> BUY within OTB
A12: =Inputs!$A$34 -> Bridal | B12: =Inputs!$B$34 -> 0.1 | C12: =IF($F$13=0,0,F12/$F$13) -> 0 | D12: =C12-B12 -> -0.1 | E12: =IF($F$13=0,"No stock yet",IF(D12>Inputs!$B$13,"OVER-INDEXED",IF(D12<-Inputs!$B$13,"UNDER-STOCKED","Balanced"))) -> No stock yet | F12: =SUMIFS('Stock Aging'!$J$6:$J$1005,'Stock Aging'!$C$6:$C$1005,$A12) -> 0 | G12: =IF(SUMIFS('Stock Aging'!$F$6:$F$1005,'Stock Aging'!$C$6:$C$1005,$A12)=0,"",SUMIFS('Stock Aging'!$H$6:$H$1005,'Stock Aging'!$C$6:$C$1005,$A12)/SUMIFS('Stock Aging'!$F$6:$F$1005,'Stock Aging'!$C$6:$C$1005,$A12)) | H12: =IF(SUMIFS('Sales Log'!$E$6:$E$1005,'Sales Log'!$B$6:$B$1005,$A12,'Sales Log'!$A$6:$A$1005,">="&(Inputs!$B$11-27),'Sales Log'!$A$6:$A$1005,"<="&Inputs!$B$11)=0,"",F12/(SUMIFS('Sales Log'!$E$6:$E$1005,'Sales Log'!$B$6:$B$1005,$A12,'Sales Log'!$A$6:$A$1005,">="&(Inputs!$B$11-27),'Sales Log'!$A$6:$A$1005,"<="&Inputs!$B$11)/4*(1-Inputs!$C$34))) | I12: =IF($B$5=0,0,INDEX('Monthly OTB'!$C$57:$N$57,$B$5)) -> 0 | J12: =SUMIFS('Stock Aging'!$N$6:$N$1005,'Stock Aging'!$C$6:$C$1005,$A12,'Stock Aging'!$O$6:$O$1005,$B$4) -> 0 | K12: =I12-J12 -> 0 | L12: =IF(K12<0,"PAUSE – over OTB budget",IF(E12="OVER-INDEXED","PAUSE PROCUREMENT",IF(AND(H12<>"",N(H12)>Inputs!$B$15),"PAUSE – too much cover",IF(AND(G12<>"",N(G12)<Inputs!$B$14),"SLOW – sell-through low",IF(E12="UNDER-STOCKED","PRIORITISE – buy up to OTB","BUY within OTB"))))) -> BUY within OTB
A13: Total | B13: =SUM(B9:B12) -> 1 | C13: =SUM(C9:C12) -> 0 | F13: =SUM(F9:F12) -> 0 | I13: =SUM(I9:I12) -> 0 | J13: =SUM(J9:J12) -> 0 | K13: =SUM(K9:K12) -> 0
A15: Sourcing run — cash to carry this month (₹ at cost)
A16: Source | B16: Approved this month | C16: Already spent | D16: Still to spend
A17: Surat | B17: =IF($B$5=0,0,INDEX('Monthly OTB'!$C$16:$N$16,$B$5)+INDEX('Monthly OTB'!$C$30:$N$30,$B$5)+INDEX('Monthly OTB'!$C$44:$N$44,$B$5)+INDEX('Monthly OTB'!$C$58:$N$58,$B$5)) -> 0 | C17: =SUMIFS('Stock Aging'!$N$6:$N$1005,'Stock Aging'!$D$6:$D$1005,$A17,'Stock Aging'!$O$6:$O$1005,$B$4) -> 0 | D17: =B17-C17 -> 0
A18: Burrabazar | B18: =IF($B$5=0,0,INDEX('Monthly OTB'!$C$17:$N$17,$B$5)+INDEX('Monthly OTB'!$C$31:$N$31,$B$5)+INDEX('Monthly OTB'!$C$45:$N$45,$B$5)+INDEX('Monthly OTB'!$C$59:$N$59,$B$5)) -> 0 | C18: =SUMIFS('Stock Aging'!$N$6:$N$1005,'Stock Aging'!$D$6:$D$1005,$A18,'Stock Aging'!$O$6:$O$1005,$B$4) -> 0 | D18: =B18-C18 -> 0
A19: Other | B19: =IF($B$5=0,0,INDEX('Monthly OTB'!$C$18:$N$18,$B$5)+INDEX('Monthly OTB'!$C$32:$N$32,$B$5)+INDEX('Monthly OTB'!$C$46:$N$46,$B$5)+INDEX('Monthly OTB'!$C$60:$N$60,$B$5)) -> 0 | C19: =SUMIFS('Stock Aging'!$N$6:$N$1005,'Stock Aging'!$D$6:$D$1005,$A19,'Stock Aging'!$O$6:$O$1005,$B$4) -> 0 | D19: =B19-C19 -> 0
A20: Total | B20: =SUM(B17:B19) -> 0 | C20: =SUM(C17:C19) -> 0 | D20: =SUM(D17:D19) -> 0
A22: Cash position
A23: Working capital | B23: =Inputs!$B$6 -> 1000000
A24: Setup costs | B24: =Inputs!$B$7 -> 250000
A25: Monthly fixed costs | B25: =Inputs!$B$27 -> 103000
A26: Cash buffer protected | B26: =Inputs!$B$27*Inputs!$B$10 -> 206000
A27: Planned sales this month | B27: =IF($B$5=0,0,INDEX('Monthly OTB'!$C$68:$N$68,$B$5)) -> 0
A28: Actual sales this month (Sales Log) | B28: =SUMIFS('Sales Log'!$E$6:$E$1005,'Sales Log'!$G$6:$G$1005,$B$4) -> 0
A29: Sales vs plan | B29: =IF(B27=0,"",B28/B27)
A30: Planned closing cash this month | B30: =IF($B$5=0,0,INDEX('Monthly OTB'!$C$73:$N$73,$B$5)) -> 0
A31: Runway (months of fixed costs) | B31: =IF($B$5=0,0,INDEX('Monthly OTB'!$C$74:$N$74,$B$5)) -> 0
A32: Cash status | B32: =IF($B$5=0,"-",INDEX('Monthly OTB'!$C$75:$N$75,$B$5)) -> -
A34: Stock aging (₹ at cost)
A35: Bucket | B35: Stock value | C35: % of stock | D35: What to do
A36: Fresh | B36: =SUMIFS('Stock Aging'!$J$6:$J$1005,'Stock Aging'!$L$6:$L$1005,$A36) -> 0 | C36: =IF(SUM($B$36:$B$39)=0,0,B36/SUM($B$36:$B$39)) -> 0 | D36: OK
A37: Watch | B37: =SUMIFS('Stock Aging'!$J$6:$J$1005,'Stock Aging'!$L$6:$L$1005,$A37) -> 0 | C37: =IF(SUM($B$36:$B$39)=0,0,B37/SUM($B$36:$B$39)) -> 0 | D37: Push in reels & WhatsApp broadcast
A38: Ageing | B38: =SUMIFS('Stock Aging'!$J$6:$J$1005,'Stock Aging'!$L$6:$L$1005,$A38) -> 0 | C38: =IF(SUM($B$36:$B$39)=0,0,B38/SUM($B$36:$B$39)) -> 0 | D38: Markdown 20-30%
A39: Dead | B39: =SUMIFS('Stock Aging'!$J$6:$J$1005,'Stock Aging'!$L$6:$L$1005,$A39) -> 0 | C39: =IF(SUM($B$36:$B$39)=0,0,B39/SUM($B$36:$B$39)) -> 0 | D39: Clearance / exchange with vendor

Sheet Inputs
A1: Inputs
A2: Yellow cells are inputs. All values are PLACEHOLDERS until you overwrite them. INR, ex-GST.
A3: General
A4: Store name | B4: Ma Lakhsmi Stores
A5: Plan start month (1st of month) | B5: 46327
A6: Working capital (₹) | B6: 1000000
A7: One-time setup costs (₹) | B7: 250000
A8: Base monthly sales, all categories (₹, selling price) | B8: 135000
A9: GST rate on sarees (reference only) | B9: 0.05
A10: Cash buffer (months of fixed costs) | B10: 2
A11: Review as-of date | B11: =TODAY() -> 46319
A12: Thresholds
A13: Mix tolerance (± share of stock) | B13: 0.05
A14: Minimum healthy sell-through | B14: 0.4
A15: Max weeks of cover | B15: 12
A16: Aging: 'Watch' after (days) | B16: 60
A17: Aging: 'Ageing / markdown' after (days) | B17: 90
A18: Aging: 'Dead stock' after (days) | B18: 120
A20: Monthly fixed costs (₹)
A21: Rent | B21: 25000
A22: Staff salaries (4) | B22: 60000
A23: Electricity | B23: 5000
A24: Loan EMI | B24: 0
A25: Marketing (WhatsApp API, ads) | B25: 8000
A26: Misc / maintenance | B26: 5000
A27: Total monthly fixed costs | B27: =SUM(B21:B26) -> 103000
A29: Categories
A30: Category | B30: Target mix % | C30: Target gross margin % | D30: Months of cover (closing stock ÷ next month sales) | E30: Opening stock (₹ at cost) | F30: Surat % | G30: Burrabazar % | H30: Other % | I30: Split check
A31: Daily Wear | B31: 0.3 | C31: 0.6 | D31: 1.5 | E31: 0 | F31: 0.7 | G31: 0.2 | H31: 0.1 | I31: =IF(ABS(SUM(F31:H31)-1)<0.0001,"OK","Must total 100%") -> OK
A32: Festive Handlooms | B32: 0.35 | C32: 0.6 | D32: 2 | E32: 0 | F32: 0.1 | G32: 0.6 | H32: 0.3 | I32: =IF(ABS(SUM(F32:H32)-1)<0.0001,"OK","Must total 100%") -> OK
A33: Party Wear Synthetics | B33: 0.25 | C33: 0.6 | D33: 1.5 | E33: 0 | F33: 0.85 | G33: 0.15 | H33: 0 | I33: =IF(ABS(SUM(F33:H33)-1)<0.0001,"OK","Must total 100%") -> OK
A34: Bridal | B34: 0.1 | C34: 0.6 | D34: 3 | E34: 0 | F34: 0.3 | G34: 0.5 | H34: 0.2 | I34: =IF(ABS(SUM(F34:H34)-1)<0.0001,"OK","Must total 100%") -> OK
A35: Total | B35: =SUM(B31:B34) -> 1 | C35: =IF(ABS(B35-1)<0.0001,"OK","Mix must total 100%") -> OK
A37: Seasonality (Jalpaiguri / Bengal festival calendar)
A38: Month | B38: Sales index (1.0 = base) | C38: Why
A39: Jan | B39: 1.1 | C39: Wedding season
A40: Feb | B40: 1.1 | C40: Wedding season, Saraswati Puja
A41: Mar | B41: 0.9 | C41: Year-end lull
A42: Apr | B42: 1.2 | C42: Poila Boishakh
A43: May | B43: 0.9 | C43: Summer, some weddings
...

Sheet Monthly OTB
A1: Monthly Open-to-Buy plan (₹ at cost unless stated)
A2: OTB = planned sales at cost + planned closing stock − opening stock − on order, then capped by cash.
A4: Month | C4: =EDATE(Inputs!$B$5,0) -> 46327 | D4: =EDATE(Inputs!$B$5,1) -> 46357 | E4: =EDATE(Inputs!$B$5,2) -> 46388 | F4: =EDATE(Inputs!$B$5,3) -> 46419 | G4: =EDATE(Inputs!$B$5,4) -> 46447 | H4: =EDATE(Inputs!$B$5,5) -> 46478 | I4: =EDATE(Inputs!$B$5,6) -> 46508 | J4: =EDATE(Inputs!$B$5,7) -> 46539 | K4: =EDATE(Inputs!$B$5,8) -> 46569 | L4: =EDATE(Inputs!$B$5,9) -> 46600 | M4: =EDATE(Inputs!$B$5,10) -> 46631 | N4: =EDATE(Inputs!$B$5,11) -> 46661
A5: Seasonality index | C5: =INDEX(Inputs!$B$39:$B$50,MONTH(C4)) -> 1.2 | D5: =INDEX(Inputs!$B$39:$B$50,MONTH(D4)) -> 1.2 | E5: =INDEX(Inputs!$B$39:$B$50,MONTH(E4)) -> 1.1 | F5: =INDEX(Inputs!$B$39:$B$50,MONTH(F4)) -> 1.1 | G5: =INDEX(Inputs!$B$39:$B$50,MONTH(G4)) -> 0.9 | H5: =INDEX(Inputs!$B$39:$B$50,MONTH(H4)) -> 1.2 | I5: =INDEX(Inputs!$B$39:$B$50,MONTH(I4)) -> 0.9 | J5: =INDEX(Inputs!$B$39:$B$50,MONTH(J4)) -> 0.7 | ... N5: =INDEX(Inputs!$B$39:$B$50,MONTH(N4)) -> 1.6
A6: Next month's index | C6: =INDEX(Inputs!$B$39:$B$50,MONTH(EDATE(C4,1))) -> 1.2 | D6: =INDEX(Inputs!$B$39:$B$50,MONTH(EDATE(D4,1))) -> 1.1 | E6: =INDEX(Inputs!$B$39:$B$50,MONTH(EDATE(E4,1))) -> 1.1 | F6: =INDEX(Inputs!$B$39:$B$50,MONTH(EDATE(F4,1))) -> 0.9 | G6: =INDEX(Inputs!$B$39:$B$50,MONTH(EDATE(G4,1))) -> 1.2 | H6: =INDEX(Inputs!$B$39:$B$50,MONTH(EDATE(H4,1))) -> 0.9 | I6: =INDEX(Inputs!$B$39:$B$50,MONTH(EDATE(I4,1))) -> 0.7 | J6: =INDEX(Inputs!$B$39:$B$50,MONTH(EDATE(J4,1))) -> 0.7 | ... N6: =INDEX(Inputs!$B$39:$B$50,MONTH(EDATE(N4,1))) -> 1.2
A8: =Inputs!$A$31 -> Daily Wear
A9: Planned sales (₹ selling price) | C9: =Inputs!$B$8*Inputs!$B$31*C$5 -> 48600 | D9: =Inputs!$B$8*Inputs!$B$31*D$5 -> 48600 | E9: =Inputs!$B$8*Inputs!$B$31*E$5 -> 44550 | F9: =Inputs!$B$8*Inputs!$B$31*F$5 -> 44550 | G9: =Inputs!$B$8*Inputs!$B$31*G$5 -> 36450 | H9: =Inputs!$B$8*Inputs!$B$31*H$5 -> 48600 | I9: =Inputs!$B$8*Inputs!$B$31*I$5 -> 36450 | J9: =Inputs!$B$8*Inputs!$B$31*J$5 -> 28350 | ... N9: =Inputs!$B$8*Inputs!$B$31*N$5 -> 64800
A10: Planned sales at cost | C10: =C9*(1-Inputs!$C$31) -> 19440 | D10: =D9*(1-Inputs!$C$31) -> 19440 | E10: =E9*(1-Inputs!$C$31) -> 17820 | F10: =F9*(1-Inputs!$C$31) -> 17820 | G10: =G9*(1-Inputs!$C$31) -> 14580 | H10: =H9*(1-Inputs!$C$31) -> 19440 | I10: =I9*(1-Inputs!$C$31) -> 14580 | J10: =J9*(1-Inputs!$C$31) -> 11340 | ... N10: =N9*(1-Inputs!$C$31) -> 25920
A11: Planned closing stock | C11: =Inputs!$B$8*Inputs!$B$31*(1-Inputs!$C$31)*C$6*Inputs!$D$31 -> 29160 | D11: =Inputs!$B$8*Inputs!$B$31*(1-Inputs!$C$31)*D$6*Inputs!$D$31 -> 26730 | E11: =Inputs!$B$8*Inputs!$B$31*(1-Inputs!$C$31)*E$6*Inputs!$D$31 -> 26730 | F11: =Inputs!$B$8*Inputs!$B$31*(1-Inputs!$C$31)*F$6*Inputs!$D$31 -> 21870 | G11: =Inputs!$B$8*Inputs!$B$31*(1-Inputs!$C$31)*G$6*Inputs!$D$31 -> 29160 | H11: =Inputs!$B$8*Inputs!$B$31*(1-Inputs!$C$31)*H$6*Inputs!$D$31 -> 21870 | I11: =Inputs!$B$8*Inputs!$B$31*(1-Inputs!$C$31)*I$6*Inputs!$D$31 -> 17010 | J11: =Inputs!$B$8*Inputs!$B$31*(1-Inputs!$C$31)*J$6*Inputs!$D$31 -> 17010 | ... N11: =Inputs!$B$8*Inputs!$B$31*(1-Inputs!$C$31)*N$6*Inputs!$D$31 -> 29160
A12: Opening stock | C12: =Inputs!$E$31 -> 0 | D12: =C11 -> 29160 | E12: =D11 -> 26730 | F12: =E11 -> 26730 | G12: =F11 -> 21870 | H12: =G11 -> 29160 | I12: =H11 -> 21870 | J12: =I11 -> 17010 | K12: =J11 -> 17010 | ... N12: =M11 -> 38880
A13: On order (enter) | C13: 0 | D13: 0 | E13: 0 | F13: 0 | G13: 0 | H13: 0 | I13: 0 | J13: 0 | K13: 0 | L13: 0 | M13: 0 | N13: 0
A14: Required OTB | C14: =MAX(0,C10+C11-C12-C13) -> 48600 | D14: =MAX(0,D10+D11-D12-D13) -> 17010 | E14: =MAX(0,E10+E11-E12-E13) -> 17820 | F14: =MAX(0,F10+F11-F12-F13) -> 12960 | G14: =MAX(0,G10+G11-G12-G13) -> 21870 | H14: =MAX(0,H10+H11-H12-H13) -> 12150 | I14: =MAX(0,I10+I11-I12-I13) -> 9720 | J14: =MAX(0,J10+J11-J12-J13) -> 11340 | ... N14: =MAX(0,N10+N11-N12-N13) -> 16200
A15: APPROVED OTB (cash-capped) | C15: =C14*C$71 -> 48600 | D15: =D14*D$71 -> 17010 | E15: =E14*E$71 -> 17820 | F15: =F14*F$71 -> 12960 | G15: =G14*G$71 -> 21870 | H15: =H14*H$71 -> 12150 | I15: =I14*I$71 -> 9720 | J15: =J14*J$71 -> 11340 | ... N15: =N14*N$71 -> 16200
A16: → carry to Surat | C16: =C15*Inputs!$F$31 -> 34020 | D16: =D15*Inputs!$F$31 -> 11907 | E16: =E15*Inputs!$F$31 -> 12474 | F16: =F15*Inputs!$F$31 -> 9072 | G16: =G15*Inputs!$F$31 -> 15309 | H16: =H15*Inputs!$F$31 -> 8505 | I16: =I15*Inputs!$F$31 -> 6804 | J16: =J15*Inputs!$F$31 -> 7938 | ... N16: =N15*Inputs!$F$31 -> 11340
A17: → carry to Burrabazar | C17: =C15*Inputs!$G$31 -> 9720 | D17: =D15*Inputs!$G$31 -> 3402 | E17: =E15*Inputs!$G$31 -> 3564 | F17: =F15*Inputs!$G$31 -> 2592 | G17: =G15*Inputs!$G$31 -> 4374 | H17: =H15*Inputs!$G$31 -> 2430 | I17: =I15*Inputs!$G$31 -> 1944 | J17: =J15*Inputs!$G$31 -> 2268 | ... N17: =N15*Inputs!$G$31 -> 3240
A18: → carry to Other | C18: =C15*Inputs!$H$31 -> 4860 | D18: =D15*Inputs!$H$31 -> 1701 | E18: =E15*Inputs!$H$31 -> 1782 | F18: =F15*Inputs!$H$31 -> 1296 | G18: =G15*Inputs!$H$31 -> 2187 | H18: =H15*Inputs!$H$31 -> 1215 | I18: =I15*Inputs!$H$31 -> 972 | J18: =J15*Inputs!$H$31 -> 1134 | ... N18: =N15*Inputs!$H$31 -> 1620
A19: Actually bought (Stock Aging) | C19: =SUMIFS('Stock Aging'!$N$6:$N$1005,'Stock Aging'!$C$6:$C$1005,$A$8,'Stock Aging'!$O$6:$O$1005,C$4) -> 0 | D19: =SUMIFS('Stock Aging'!$N$6:$N$1005,'Stock Aging'!$C$6:$C$1005,$A$8,'Stock Aging'!$O$6:$O$1005,D$4) -> 0 | E19: =SUMIFS('Stock Aging'!$N$6:$N$1005,'Stock Aging'!$C$6:$C$1005,$A$8,'Stock Aging'!$O$6:$O$1005,E$4) -> 0 | F19: =SUMIFS('Stock Aging'!$N$6:$N$1005,'Stock Aging'!$C$6:$C$1005,$A$8,'Stock Aging'!$O$6:$O$1005,F$4) -> 0 | G19: =SUMIFS('Stock Aging'!$N$6:$N$1005,'Stock Aging'!$C$6:$C$1005,$A$8,'Stock Aging'!$O$6:$O$1005,G$4) -> 0 | H19: =SUMIFS('Stock Aging'!$N$6:$N$1005,'Stock Aging'!$C$6:$C$1005,$A$8,'Stock Aging'!$O$6:$O$1005,H$4) -> 0 | I19: =SUMIFS('Stock Aging'!$N$6:$N$1005,'Stock Aging'!$C$6:$C$1005,$A$8,'Stock Aging'!$O$6:$O$1005,I$4) -> 0 | J19: =SUMIFS('Stock Aging'!$N$6:$N$1005,'Stock Aging'!$C$6:$C$1005,$A$8,'Stock Aging'!$O$6:$O$1005,J$4) -> 0 | ... N19: =SUMIFS('Stock Aging'!$N$6:$N$1005,'Stock Aging'!$C$6:$C$1005,$A$8,'Stock Aging'!$O$6:$O$1005,N$4) -> 0
A20: OTB remaining | C20: =C15-C19 -> 48600 | D20: =D15-D19 -> 17010 | E20: =E15-E19 -> 17820 | F20: =F15-F19 -> 12960 | G20: =G15-G19 -> 21870 | H20: =H15-H19 -> 12150 | I20: =I15-I19 -> 9720 | J20: =J15-J19 -> 11340 | ... N20: =N15-N19 -> 16200
A22: =Inputs!$A$32 -> Festive Handlooms
A23: Planned sales (₹ selling price) | C23: =Inputs!$B$8*Inputs!$B$32*C$5 -> 56700 | D23: =Inputs!$B$8*Inputs!$B$32*D$5 -> 56700 | E23: =Inputs!$B$8*Inputs!$B$32*E$5 -> 51975 | F23: =Inputs!$B$8*Inputs!$B$32*F$5 -> 51975 | G23: =Inputs!$B$8*Inputs!$B$32*G$5 -> 42525 | H23: =Inputs!$B$8*Inputs!$B$32*H$5 -> 56700 | I23: =Inputs!$B$8*Inputs!$B$32*I$5 -> 42525 | J23: =Inputs!$B$8*Inputs!$B$32*J$5 -> 33075 | ... N23: =Inputs!$B$8*Inputs!$B$32*N$5 -> 75600
A24: Planned sales at cost | C24: =C23*(1-Inputs!$C$32) -> 22680 | D24: =D23*(1-Inputs!$C$32) -> 22680 | E24: =E23*(1-Inputs!$C$32) -> 20790 | F24: =F23*(1-Inputs!$C$32) -> 20790 | G24: =G23*(1-Inputs!$C$32) -> 17010 | H24: =H23*(1-Inputs!$C$32) -> 22680 | I24: =I23*(1-Inputs!$C$32) -> 17010 | J24: =J23*(1-Inputs!$C$32) -> 13230 | ... N24: =N23*(1-Inputs!$C$32) -> 30240
A25: Planned closing stock | C25: =Inputs!$B$8*Inputs!$B$32*(1-Inputs!$C$32)*C$6*Inputs!$D$32 -> 45360 | D25: =Inputs!$B$8*Inputs!$B$32*(1-Inputs!$C$32)*D$6*Inputs!$D$32 -> 41580 | E25: =Inputs!$B$8*Inputs!$B$32*(1-Inputs!$C$32)*E$6*Inputs!$D$32 -> 41580 | F25: =Inputs!$B$8*Inputs!$B$32*(1-Inputs!$C$32)*F$6*Inputs!$D$32 -> 34020 | G25: =Inputs!$B$8*Inputs!$B$32*(1-Inputs!$C$32)*G$6*Inputs!$D$32 -> 45360 | H25: =Inputs!$B$8*Inputs!$B$32*(1-Inputs!$C$32)*H$6*Inputs!$D$32 -> 34020 | I25: =Inputs!$B$8*Inputs!$B$32*(1-Inputs!$C$32)*I$6*Inputs!$D$32 -> 26460 | J25: =Inputs!$B$8*Inputs!$B$32*(1-Inputs!$C$32)*J$6*Inputs!$D$32 -> 26460 | ... N25: =Inputs!$B$8*Inputs!$B$32*(1-Inputs!$C$32)*N$6*Inputs!$D$32 -> 45360
A26: Opening stock | C26: =Inputs!$E$32 -> 0 | D26: =C25 -> 45360 | E26: =D25 -> 41580 | F26: =E25 -> 41580 | G26: =F25 -> 34020 | H26: =G25 -> 45360 | I26: =H25 -> 34020 | J26: =I25 -> 26460 | K26: =J25 -> 26460 | ... N26: =M25 -> 60480
A27: On order (enter) | C27: 0 | D27: 0 | E27: 0 | F27: 0 | G27: 0 | H27: 0 | I27: 0 | J27: 0 | K27: 0 | L27: 0 | M27: 0 | N27: 0
A28: Required OTB | C28: =MAX(0,C24+C25-C26-C27) -> 68040 | D28: =MAX(0,D24+D25-D26-D27) -> 18900 | E28: =MAX(0,E24+E25-E26-E27) -> 20790 | F28: =MAX(0,F24+F25-F26-F27) -> 13230 | G28: =MAX(0,G24+G25-G26-G27) -> 28350 | H28: =MAX(0,H24+H25-H26-H27) -> 11340 | I28: =MAX(0,I24+I25-I26-I27) -> 9450 | J28: =MAX(0,J24+J25-J26-J27) -> 13230 | ... N28: =MAX(0,N24+N25-N26-N27) -> 15120
A29: APPROVED OTB (cash-capped) | C29: =C28*C$71 -> 68040 | D29: =D28*D$71 -> 18900 | E29: =E28*E$71 -> 20790 | F29: =F28*F$71 -> 13230 | G29: =G28*G$71 -> 28350 | H29: =H28*H$71 -> 11340 | I29: =I28*I$71 -> 9450 | J29: =J28*J$71 -> 13230 | ... N29: =N28*N$71 -> 15120
A30: → carry to Surat | C30: =C29*Inputs!$F$32 -> 6804 | D30: =D29*Inputs!$F$32 -> 1890 | E30: =E29*Inputs!$F$32 -> 2079 | F30: =F29*Inputs!$F$32 -> 1323 | G30: =G29*Inputs!$F$32 -> 2835 | H30: =H29*Inputs!$F$32 -> 1134 | I30: =I29*Inputs!$F$32 -> 945 | J30: =J29*Inputs!$F$32 -> 1323 | ... N30: =N29*Inputs!$F$32 -> 1512
A31: → carry to Burrabazar | C31: =C29*Inputs!$G$32 -> 40824 | D31: =D29*Inputs!$G$32 -> 11340 | E31: =E29*Inputs!$G$32 -> 12474 | F31: =F29*Inputs!$G$32 -> 7938 | G31: =G29*Inputs!$G$32 -> 17010 | H31: =H29*Inputs!$G$32 -> 6804 | I31: =I29*Inputs!$G$32 -> 5670 | J31: =J29*Inputs!$G$32 -> 7938 | ... N31: =N29*Inputs!$G$32 -> 9072
A32: → carry to Other | C32: =C29*Inputs!$H$32 -> 20412 | D32: =D29*Inputs!$H$32 -> 5670 | E32: =E29*Inputs!$H$32 -> 6237 | F32: =F29*Inputs!$H$32 -> 3969 | G32: =G29*Inputs!$H$32 -> 8505 | H32: =H29*Inputs!$H$32 -> 3402 | I32: =I29*Inputs!$H$32 -> 2835 | J32: =J29*Inputs!$H$32 -> 3969 | ... N32: =N29*Inputs!$H$32 -> 4536
A33: Actually bought (Stock Aging) | C33: =SUMIFS('Stock Aging'!$N$6:$N$1005,'Stock Aging'!$C$6:$C$1005,$A$22,'Stock Aging'!$O$6:$O$1005,C$4) -> 0 | D33: =SUMIFS('Stock Aging'!$N$6:$N$1005,'Stock Aging'!$C$6:$C$1005,$A$22,'Stock Aging'!$O$6:$O$1005,D$4) -> 0 | E33: =SUMIFS('Stock Aging'!$N$6:$N$1005,'Stock Aging'!$C$6:$C$1005,$A$22,'Stock Aging'!$O$6:$O$1005,E$4) -> 0 | F33: =SUMIFS('Stock Aging'!$N$6:$N$1005,'Stock Aging'!$C$6:$C$1005,$A$22,'Stock Aging'!$O$6:$O$1005,F$4) -> 0 | G33: =SUMIFS('Stock Aging'!$N$6:$N$1005,'Stock Aging'!$C$6:$C$1005,$A$22,'Stock Aging'!$O$6:$O$1005,G$4) -> 0 | H33: =SUMIFS('Stock Aging'!$N$6:$N$1005,'Stock Aging'!$C$6:$C$1005,$A$22,'Stock Aging'!$O$6:$O$1005,H$4) -> 0 | I33: =SUMIFS('Stock Aging'!$N$6:$N$1005,'Stock Aging'!$C$6:$C$1005,$A$22,'Stock Aging'!$O$6:$O$1005,I$4) -> 0 | J33: =SUMIFS('Stock Aging'!$N$6:$N$1005,'Stock Aging'!$C$6:$C$1005,$A$22,'Stock Aging'!$O$6:$O$1005,J$4) -> 0 | ... N33: =SUMIFS('Stock Aging'!$N$6:$N$1005,'Stock Aging'!$C$6:$C$1005,$A$22,'Stock Aging'!$O$6:$O$1005,N$4) -> 0
A34: OTB remaining | C34: =C29-C33 -> 68040 | D34: =D29-D33 -> 18900 | E34: =E29-E33 -> 20790 | F34: =F29-F33 -> 13230 | G34: =G29-G33 -> 28350 | H34: =H29-H33 -> 11340 | I34: =I29-I33 -> 9450 | J34: =J29-J33 -> 13230 | ... N34: =N29-N33 -> 15120
A36: =Inputs!$A$33 -> Party Wear Synthetics
A37: Planned sales (₹ selling price) | C37: =Inputs!$B$8*Inputs!$B$33*C$5 -> 40500 | D37: =Inputs!$B$8*Inputs!$B$33*D$5 -> 40500 | E37: =Inputs!$B$8*Inputs!$B$33*E$5 -> 37125 | F37: =Inputs!$B$8*Inputs!$B$33*F$5 -> 37125 | G37: =Inputs!$B$8*Inputs!$B$33*G$5 -> 30375 | H37: =Inputs!$B$8*Inputs!$B$33*H$5 -> 40500 | I37: =Inputs!$B$8*Inputs!$B$33*I$5 -> 30375 | J37: =Inputs!$B$8*Inputs!$B$33*J$5 -> 23625 | ... N37: =Inputs!$B$8*Inputs!$B$33*N$5 -> 54000
A38: Planned sales at cost | C38: =C37*(1-Inputs!$C$33) -> 16200 | D38: =D37*(1-Inputs!$C$33) -> 16200 | E38: =E37*(1-Inputs!$C$33) -> 14850 | F38: =F37*(1-Inputs!$C$33) -> 14850 | G38: =G37*(1-Inputs!$C$33) -> 12150 | H38: =H37*(1-Inputs!$C$33) -> 16200 | I38: =I37*(1-Inputs!$C$33) -> 12150 | J38: =J37*(1-Inputs!$C$33) -> 9450 | ... N38: =N37*(1-Inputs!$C$33) -> 21600
A39: Planned closing stock | C39: =Inputs!$B$8*Inputs!$B$33*(1-Inputs!$C$33)*C$6*Inputs!$D$33 -> 24300 | D39: =Inputs!$B$8*Inputs!$B$33*(1-Inputs!$C$33)*D$6*Inputs!$D$33 -> 22275 | E39: =Inputs!$B$8*Inputs!$B$33*(1-Inputs!$C$33)*E$6*Inputs!$D$33 -> 22275 | F39: =Inputs!$B$8*Inputs!$B$33*(1-Inputs!$C$33)*F$6*Inputs!$D$33 -> 18225 | G39: =Inputs!$B$8*Inputs!$B$33*(1-Inputs!$C$33)*G$6*Inputs!$D$33 -> 24300 | H39: =Inputs!$B$8*Inputs!$B$33*(1-Inputs!$C$33)*H$6*Inputs!$D$33 -> 18225 | I39: =Inputs!$B$8*Inputs!$B$33*(1-Inputs!$C$33)*I$6*Inputs!$D$33 -> 14175 | J39: =Inputs!$B$8*Inputs!$B$33*(1-Inputs!$C$33)*J$6*Inputs!$D$33 -> 14175 | ... N39: =Inputs!$B$8*Inputs!$B$33*(1-Inputs!$C$33)*N$6*Inputs!$D$33 -> 24300
A40: Opening stock | C40: =Inputs!$E$33 -> 0 | D40: =C39 -> 24300 | E40: =D39 -> 22275 | F40: =E39 -> 22275 | G40: =F39 -> 18225 | H40: =G39 -> 24300 | I40: =H39 -> 18225 | J40: =I39 -> 14175 | K40: =J39 -> 14175 | ... N40: =M39 -> 32400
A41: On order (enter) | C41: 0 | D41: 0 | E41: 0 | F41: 0 | G41: 0 | H41: 0 | I41: 0 | J41: 0 | K41: 0 | L41: 0 | M41: 0 | N41: 0
A42: Required OTB | C42: =MAX(0,C38+C39-C40-C41) -> 40500 | D42: =MAX(0,D38+D39-D40-D41) -> 14175 | E42: =MAX(0,E38+E39-E40-E41) -> 14850 | F42: =MAX(0,F38+F39-F40-F41) -> 10800 | G42: =MAX(0,G38+G39-G40-G41) -> 18225 | H42: =MAX(0,H38+H39-H40-H41) -> 10125 | I42: =MAX(0,I38+I39-I40-I41) -> 8100 | J42: =MAX(0,J38+J39-J40-J41) -> 9450 | ... N42: =MAX(0,N38+N39-N40-N41) -> 13500
A43: APPROVED OTB (cash-capped) | C43: =C42*C$71 -> 40500 | D43: =D42*D$71 -> 14175 | E43: =E42*E$71 -> 14850 | F43: =F42*F$71 -> 10800 | G43: =G42*G$71 -> 18225 | H43: =H42*H$71 -> 10125 | I43: =I42*I$71 -> 8100 | J43: =J42*J$71 -> 9450 | ... N43: =N42*N$71 -> 13500
A44: → carry to Surat | C44: =C43*Inputs!$F$33 -> 34425 | D44: =D43*Inputs!$F$33 -> 12048.75 | E44: =E43*Inputs!$F$33 -> 12622.5 | F44: =F43*Inputs!$F$33 -> 9180 | G44: =G43*Inputs!$F$33 -> 15491.25 | H44: =H43*Inputs!$F$33 -> 8606.25 | I44: =I43*Inputs!$F$33 -> 6885 | J44: =J43*Inputs!$F$33 -> 8032.5 | ... N44: =N43*Inputs!$F$33 -> 11475
...

Sheet Sales Log
A1: Sales Log — enter weekly
A2: One row per week × category × source. Sales ₹ at selling price, ex-GST.
A3: 46328 | B3: Daily Wear | C3: Surat | D3: 14 | E3: 16800 | F3: EXAMPLE ROW — not counted
A5: Week start date | B5: Category | C5: Source | D5: Units sold | E5: Sales ₹ (selling price, ex-GST) | F5: Notes | G5: Month (auto)
G6: =IF(A6="","",DATE(YEAR(A6),MONTH(A6),1))
G7: =IF(A7="","",DATE(YEAR(A7),MONTH(A7),1))
G8: =IF(A8="","",DATE(YEAR(A8),MONTH(A8),1))
G9: =IF(A9="","",DATE(YEAR(A9),MONTH(A9),1))
G10: =IF(A10="","",DATE(YEAR(A10),MONTH(A10),1))
G11: =IF(A11="","",DATE(YEAR(A11),MONTH(A11),1))
G12: =IF(A12="","",DATE(YEAR(A12),MONTH(A12),1))
G13: =IF(A13="","",DATE(YEAR(A13),MONTH(A13),1))
G14: =IF(A14="","",DATE(YEAR(A14),MONTH(A14),1))
G15: =IF(A15="","",DATE(YEAR(A15),MONTH(A15),1))
G16: =IF(A16="","",DATE(YEAR(A16),MONTH(A16),1))
G17: =IF(A17="","",DATE(YEAR(A17),MONTH(A17),1))
... G1005: =IF(A1005="","",DATE(YEAR(A1005),MONTH(A1005),1))

Sheet Stock Aging
A1: Stock Aging — one row per purchase lot
A2: Doubles as the purchase register: what you buy here is what counts against OTB. Update 'Qty sold' weekly.
A3: SUR-2611-01 | B3: 46329 | C3: Daily Wear | D3: Surat | E3: Printed cotton, 6.3m | F3: 40 | G3: 480 | H3: 12 | I3: ← example only, not counted
A5: Lot ID | B5: Purchase date | C5: Category | D5: Source | E5: Description / fabric | F5: Qty bought | G5: Unit cost (₹) | H5: Qty sold | I5: Qty left | J5: Stock value (₹ at cost) | K5: Days held | L5: Bucket | M5: Action | N5: Purchase value (₹) | O5: Purchase month (auto)
I6: =IF(A6="","",F6-H6) | J6: =IF(A6="","",I6*G6) | K6: =IF(A6="","",Inputs!$B$11-B6) | L6: =IF(A6="","",IF(I6<=0,"Sold out",IF(K6>=Inputs!$B$18,"Dead",IF(K6>=Inputs!$B$17,"Ageing",IF(K6>=Inputs!$B$16,"Watch","Fresh"))))) | M6: =IF(L6="","",IF(L6="Dead","Clearance / exchange with vendor",IF(L6="Ageing","Markdown 20-30%",IF(L6="Watch","Push in reels & WhatsApp broadcast",IF(L6="Fresh","OK","-"))))) | N6: =IF(A6="","",F6*G6) | O6: =IF(B6="","",DATE(YEAR(B6),MONTH(B6),1))
I7: =IF(A7="","",F7-H7) | J7: =IF(A7="","",I7*G7) | K7: =IF(A7="","",Inputs!$B$11-B7) | L7: =IF(A7="","",IF(I7<=0,"Sold out",IF(K7>=Inputs!$B$18,"Dead",IF(K7>=Inputs!$B$17,"Ageing",IF(K7>=Inputs!$B$16,"Watch","Fresh"))))) | M7: =IF(L7="","",IF(L7="Dead","Clearance / exchange with vendor",IF(L7="Ageing","Markdown 20-30%",IF(L7="Watch","Push in reels & WhatsApp broadcast",IF(L7="Fresh","OK","-"))))) | N7: =IF(A7="","",F7*G7) | O7: =IF(B7="","",DATE(YEAR(B7),MONTH(B7),1))
I8: =IF(A8="","",F8-H8) | J8: =IF(A8="","",I8*G8) | K8: =IF(A8="","",Inputs!$B$11-B8) | L8: =IF(A8="","",IF(I8<=0,"Sold out",IF(K8>=Inputs!$B$18,"Dead",IF(K8>=Inputs!$B$17,"Ageing",IF(K8>=Inputs!$B$16,"Watch","Fresh"))))) | M8: =IF(L8="","",IF(L8="Dead","Clearance / exchange with vendor",IF(L8="Ageing","Markdown 20-30%",IF(L8="Watch","Push in reels & WhatsApp broadcast",IF(L8="Fresh","OK","-"))))) | N8: =IF(A8="","",F8*G8) | O8: =IF(B8="","",DATE(YEAR(B8),MONTH(B8),1))
I9: =IF(A9="","",F9-H9) | J9: =IF(A9="","",I9*G9) | K9: =IF(A9="","",Inputs!$B$11-B9) | L9: =IF(A9="","",IF(I9<=0,"Sold out",IF(K9>=Inputs!$B$18,"Dead",IF(K9>=Inputs!$B$17,"Ageing",IF(K9>=Inputs!$B$16,"Watch","Fresh"))))) | M9: =IF(L9="","",IF(L9="Dead","Clearance / exchange with vendor",IF(L9="Ageing","Markdown 20-30%",IF(L9="Watch","Push in reels & WhatsApp broadcast",IF(L9="Fresh","OK","-"))))) | N9: =IF(A9="","",F9*G9) | O9: =IF(B9="","",DATE(YEAR(B9),MONTH(B9),1))
I10: =IF(A10="","",F10-H10) | J10: =IF(A10="","",I10*G10) | K10: =IF(A10="","",Inputs!$B$11-B10) | L10: =IF(A10="","",IF(I10<=0,"Sold out",IF(K10>=Inputs!$B$18,"Dead",IF(K10>=Inputs!$B$17,"Ageing",IF(K10>=Inputs!$B$16,"Watch","Fresh"))))) | M10: =IF(L10="","",IF(L10="Dead","Clearance / exchange with vendor",IF(L10="Ageing","Markdown 20-30%",IF(L10="Watch","Push in reels & WhatsApp broadcast",IF(L10="Fresh","OK","-"))))) | N10: =IF(A10="","",F10*G10) | O10: =IF(B10="","",DATE(YEAR(B10),MONTH(B10),1))
I11: =IF(A11="","",F11-H11) | J11: =IF(A11="","",I11*G11) | K11: =IF(A11="","",Inputs!$B$11-B11) | L11: =IF(A11="","",IF(I11<=0,"Sold out",IF(K11>=Inputs!$B$18,"Dead",IF(K11>=Inputs!$B$17,"Ageing",IF(K11>=Inputs!$B$16,"Watch","Fresh"))))) | M11: =IF(L11="","",IF(L11="Dead","Clearance / exchange with vendor",IF(L11="Ageing","Markdown 20-30%",IF(L11="Watch","Push in reels & WhatsApp broadcast",IF(L11="Fresh","OK","-"))))) | N11: =IF(A11="","",F11*G11) | O11: =IF(B11="","",DATE(YEAR(B11),MONTH(B11),1))
I12: =IF(A12="","",F12-H12) | J12: =IF(A12="","",I12*G12) | K12: =IF(A12="","",Inputs!$B$11-B12) | L12: =IF(A12="","",IF(I12<=0,"Sold out",IF(K12>=Inputs!$B$18,"Dead",IF(K12>=Inputs!$B$17,"Ageing",IF(K12>=Inputs!$B$16,"Watch","Fresh"))))) | M12: =IF(L12="","",IF(L12="Dead","Clearance / exchange with vendor",IF(L12="Ageing","Markdown 20-30%",IF(L12="Watch","Push in reels & WhatsApp broadcast",IF(L12="Fresh","OK","-"))))) | N12: =IF(A12="","",F12*G12) | O12: =IF(B12="","",DATE(YEAR(B12),MONTH(B12),1))
I13: =IF(A13="","",F13-H13) | J13: =IF(A13="","",I13*G13) | K13: =IF(A13="","",Inputs!$B$11-B13) | L13: =IF(A13="","",IF(I13<=0,"Sold out",IF(K13>=Inputs!$B$18,"Dead",IF(K13>=Inputs!$B$17,"Ageing",IF(K13>=Inputs!$B$16,"Watch","Fresh"))))) | M13: =IF(L13="","",IF(L13="Dead","Clearance / exchange with vendor",IF(L13="Ageing","Markdown 20-30%",IF(L13="Watch","Push in reels & WhatsApp broadcast",IF(L13="Fresh","OK","-"))))) | N13: =IF(A13="","",F13*G13) | O13: =IF(B13="","",DATE(YEAR(B13),MONTH(B13),1))
I14: =IF(A14="","",F14-H14) | J14: =IF(A14="","",I14*G14) | K14: =IF(A14="","",Inputs!$B$11-B14) | L14: =IF(A14="","",IF(I14<=0,"Sold out",IF(K14>=Inputs!$B$18,"Dead",IF(K14>=Inputs!$B$17,"Ageing",IF(K14>=Inputs!$B$16,"Watch","Fresh"))))) | M14: =IF(L14="","",IF(L14="Dead","Clearance / exchange with vendor",IF(L14="Ageing","Markdown 20-30%",IF(L14="Watch","Push in reels & WhatsApp broadcast",IF(L14="Fresh","OK","-"))))) | N14: =IF(A14="","",F14*G14) | O14: =IF(B14="","",DATE(YEAR(B14),MONTH(B14),1))
I15: =IF(A15="","",F15-H15) | J15: =IF(A15="","",I15*G15) | K15: =IF(A15="","",Inputs!$B$11-B15) | L15: =IF(A15="","",IF(I15<=0,"Sold out",IF(K15>=Inputs!$B$18,"Dead",IF(K15>=Inputs!$B$17,"Ageing",IF(K15>=Inputs!$B$16,"Watch","Fresh"))))) | M15: =IF(L15="","",IF(L15="Dead","Clearance / exchange with vendor",IF(L15="Ageing","Markdown 20-30%",IF(L15="Watch","Push in reels & WhatsApp broadcast",IF(L15="Fresh","OK","-"))))) | N15: =IF(A15="","",F15*G15) | O15: =IF(B15="","",DATE(YEAR(B15),MONTH(B15),1))
I16: =IF(A16="","",F16-H16) | J16: =IF(A16="","",I16*G16) | K16: =IF(A16="","",Inputs!$B$11-B16) | L16: =IF(A16="","",IF(I16<=0,"Sold out",IF(K16>=Inputs!$B$18,"Dead",IF(K16>=Inputs!$B$17,"Ageing",IF(K16>=Inputs!$B$16,"Watch","Fresh"))))) | M16: =IF(L16="","",IF(L16="Dead","Clearance / exchange with vendor",IF(L16="Ageing","Markdown 20-30%",IF(L16="Watch","Push in reels & WhatsApp broadcast",IF(L16="Fresh","OK","-"))))) | N16: =IF(A16="","",F16*G16) | O16: =IF(B16="","",DATE(YEAR(B16),MONTH(B16),1))
I17: =IF(A17="","",F17-H17) | J17: =IF(A17="","",I17*G17) | K17: =IF(A17="","",Inputs!$B$11-B17) | L17: =IF(A17="","",IF(I17<=0,"Sold out",IF(K17>=Inputs!$B$18,"Dead",IF(K17>=Inputs!$B$17,"Ageing",IF(K17>=Inputs!$B$16,"Watch","Fresh"))))) | M17: =IF(L17="","",IF(L17="Dead","Clearance / exchange with vendor",IF(L17="Ageing","Markdown 20-30%",IF(L17="Watch","Push in reels & WhatsApp broadcast",IF(L17="Fresh","OK","-"))))) | N17: =IF(A17="","",F17*G17) | O17: =IF(B17="","",DATE(YEAR(B17),MONTH(B17),1))
... I1005: =IF(A1005="","",F1005-H1005) | J1005: =IF(A1005="","",I1005*G1005) | K1005: =IF(A1005="","",Inputs!$B$11-B1005) | L1005: =IF(A1005="","",IF(I1005<=0,"Sold out",IF(K1005>=Inputs!$B$18,"Dead",IF(K1005>=Inputs!$B$17,"Ageing",IF(K1005>=Inputs!$B$16,"Watch","Fresh"))))) | M1005: =IF(L1005="","",IF(L1005="Dead","Clearance / exchange with vendor",IF(L1005="Ageing","Markdown 20-30%",IF(L1005="Watch","Push in reels & WhatsApp broadcast",IF(L1005="Fresh","OK","-"))))) | N1005: =IF(A1005="","",F1005*G1005) | O1005: =IF(B1005="","",DATE(YEAR(B1005),MONTH(B1005),1))
